2019-06-30 12:34:35,521ERROR:Exception on /follow/mdevaney [GET][inc:\matt's~1\python\microb~1\venv\lib\site-packages\flask\app.py:1780]
Traceback (most recent call last):
  File "c:\matt's~1\python\microb~1\venv\lib\site-packages\flask\app.py", line 2311, in wsgi_app
    response = self.full_dispatch_request()
  File "c:\matt's~1\python\microb~1\venv\lib\site-packages\flask\app.py", line 1834, in full_dispatch_request
    rv = self.handle_user_exception(e)
  File "c:\matt's~1\python\microb~1\venv\lib\site-packages\flask\app.py", line 1737, in handle_user_exception
    reraise(exc_type, exc_value, tb)
  File "c:\matt's~1\python\microb~1\venv\lib\site-packages\flask\_compat.py", line 36, in reraise
    raise value
  File "c:\matt's~1\python\microb~1\venv\lib\site-packages\flask\app.py", line 1832, in full_dispatch_request
    rv = self.dispatch_request()
  File "c:\matt's~1\python\microb~1\venv\lib\site-packages\flask\app.py", line 1818, in dispatch_request
    return self.view_functions[rule.endpoint](**req.view_args)
  File "c:\matt's~1\python\microb~1\venv\lib\site-packages\flask_login\utils.py", line 261, in decorated_view
    return func(*args, **kwargs)
  File "C:\Matt's Files\Python\microblog\app\routes.py", line 103, in follow
    user = User.query.filter_by(username=username).first()
UnboundLocalError: local variable 'user' referenced before assignment
